Traceback (most recent call last):
  File "/Users/administrator/hzw_save/code/python/UI/Common/common3.py", line 350, in fc_id_click
    self.driver.find_element_by_id(id).click()
  File "/Library/Frameworks/Python.framework/Versions/3.6/lib/python3.6/site-packages/selenium/webdriver/remote/webdriver.py", line 360, in find_element_by_id
    return self.find_element(by=By.ID, value=id_)
  File "/Library/Frameworks/Python.framework/Versions/3.6/lib/python3.6/site-packages/appium/webdriver/webdriver.py", line 284, in find_element
    'value': value})['value']
  File "/Library/Frameworks/Python.framework/Versions/3.6/lib/python3.6/site-packages/selenium/webdriver/remote/webdriver.py", line 319, in execute
    response = self.command_executor.execute(driver_command, params)
  File "/Library/Frameworks/Python.framework/Versions/3.6/lib/python3.6/site-packages/selenium/webdriver/remote/remote_connection.py", line 374, in execute
    return self._request(command_info[0], url, body=data)
  File "/Library/Frameworks/Python.framework/Versions/3.6/lib/python3.6/site-packages/selenium/webdriver/remote/remote_connection.py", line 397, in _request
    resp = self._conn.request(method, url, body=body, headers=headers)
  File "/Library/Frameworks/Python.framework/Versions/3.6/lib/python3.6/site-packages/urllib3/request.py", line 80, in request
    method, url, fields=fields, headers=headers, **urlopen_kw
  File "/Library/Frameworks/Python.framework/Versions/3.6/lib/python3.6/site-packages/urllib3/request.py", line 171, in request_encode_body
    return self.urlopen(method, url, **extra_kw)
  File "/Library/Frameworks/Python.framework/Versions/3.6/lib/python3.6/site-packages/urllib3/poolmanager.py", line 330, in urlopen
    response = conn.urlopen(method, u.request_uri, **kw)
  File "/Library/Frameworks/Python.framework/Versions/3.6/lib/python3.6/site-packages/urllib3/connectionpool.py", line 672, in urlopen
    chunked=chunked,
  File "/Library/Frameworks/Python.framework/Versions/3.6/lib/python3.6/site-packages/urllib3/connectionpool.py", line 421, in _make_request
    six.raise_from(e, None)
  File "<string>", line 3, in raise_from
  File "/Library/Frameworks/Python.framework/Versions/3.6/lib/python3.6/site-packages/urllib3/connectionpool.py", line 416, in _make_request
    httplib_response = conn.getresponse()
  File "/Library/Frameworks/Python.framework/Versions/3.6/lib/python3.6/http/client.py", line 1331, in getresponse
    response.begin()
  File "/Library/Frameworks/Python.framework/Versions/3.6/lib/python3.6/http/client.py", line 297, in begin
    version, status, reason = self._read_status()
  File "/Library/Frameworks/Python.framework/Versions/3.6/lib/python3.6/http/client.py", line 258, in _read_status
    line = str(self.fp.readline(_MAXLINE + 1), "iso-8859-1")
  File "/Library/Frameworks/Python.framework/Versions/3.6/lib/python3.6/socket.py", line 586, in readinto
    return self._sock.recv_into(b)
KeyboardInterrupt

During handling of the above exception, another exception occurred:

Traceback (most recent call last):
  File "/Users/administrator/hzw_save/code/python/UI/Main/main.py", line 48, in <module>
    a.start_run(5)
  File "/Users/administrator/hzw_save/code/python/UI/Main/main.py", line 25, in start_run
    self.really=getattr(self.kdt, keyword)(*params)
  File "/Users/administrator/hzw_save/code/python/UI/Common/common3.py", line 352, in fc_id_click
    self.error_information(egnum)
  File "/Users/administrator/hzw_save/code/python/UI/Common/common3.py", line 194, in error_information
    '../Screenshot/Error/{}-{}-{}.png'.format(self.num, egnum, self.nowtime))
  File "/Library/Frameworks/Python.framework/Versions/3.6/lib/python3.6/site-packages/selenium/webdriver/remote/webdriver.py", line 1032, in get_screenshot_as_file
    png = self.get_screenshot_as_png()
  File "/Library/Frameworks/Python.framework/Versions/3.6/lib/python3.6/site-packages/selenium/webdriver/remote/webdriver.py", line 1064, in get_screenshot_as_png
    return base64.b64decode(self.get_screenshot_as_base64().encode('ascii'))
  File "/Library/Frameworks/Python.framework/Versions/3.6/lib/python3.6/site-packages/selenium/webdriver/remote/webdriver.py", line 1074, in get_screenshot_as_base64
    return self.execute(Command.SCREENSHOT)['value']
  File "/Library/Frameworks/Python.framework/Versions/3.6/lib/python3.6/site-packages/selenium/webdriver/remote/webdriver.py", line 321, in execute
    self.error_handler.check_response(response)
  File "/Library/Frameworks/Python.framework/Versions/3.6/lib/python3.6/site-packages/appium/webdriver/errorhandler.py", line 29, in check_response
    raise wde
  File "/Library/Frameworks/Python.framework/Versions/3.6/lib/python3.6/site-packages/appium/webdriver/errorhandler.py", line 24, in check_response
    super(MobileErrorHandler, self).check_response(response)
  File "/Library/Frameworks/Python.framework/Versions/3.6/lib/python3.6/site-packages/selenium/webdriver/remote/errorhandler.py", line 242, in check_response
    raise exception_class(message, screen, stacktrace)
selenium.common.exceptions.WebDriverException: Message: An unknown server-side error occurred while processing the command. Original error: Could not proxy command to remote server. Original error: Error: socket hang up

